<?xml version="1.0" ?>

<mujoco model="autotug">
    <compiler angle="radian" meshdir="assets" autolimits="true"/>

    <option noslip_iterations="10" noslip_tolerance="1e-6"/>

    <option>
        <flag gravity="enable"/>
    </option>

    <!-- Enhanced no-slip solver -->
    <option timestep="0.005"
            iterations="20"
            tolerance="1e-12"
            solver="Newton"
            jacobian="dense"
            noslip_iterations="10"
            noslip_tolerance="1e-6"/>

    <default>
        <default class="autotug">
            <joint frictionloss="0.1" armature="0.005"/>
            <position kp="50" dampratio="1"/>

            <default class="body">
                <geom type="mesh" contype="1" conaffinity="1" group="1"/>
            </default>

            <default class="shaft">
                <geom type="mesh" contype="0" conaffinity="0" group="2"/>
            </default>

            <default class="tires-visual">
                <geom type="mesh" contype="0" conaffinity="0" group="2"/>
            </default>
            <default class="tires-collision">
                <geom type="mesh" contype="2" conaffinity="2" group="2"/>
            </default>

        </default>
    </default>


    <asset>
        <!-- Vehicle Materials  -->
        <mesh name="vehicle_mesh" file="MT340-BODY.stl"/>
        <mesh name="wheel_fl_mesh" file="MT340-WHEEL-FRONT-LEFT.stl"/>
        <mesh name="wheel_fr_mesh" file="MT340-WHEEL-FRONT-RIGHT.stl"/>
        <mesh name="wheel_rl_mesh" file="MT340-WHEEL-REAR-LEFT.stl"/>
        <mesh name="wheel_rr_mesh" file="MT340-WHEEL-REAR-RIGHT.stl"/>
        <mesh name="front_axle_mesh" file="MT340-FRONT-AXLE.stl"/>
        <material name="vehicle_material" rgba="0.4 0.0 0.0 1"/>
        <material name="shaft_material" rgba="0.8 0.8 0.8 1"/>
        <material name="wheel_mat" rgba="0.2 0.2 0.2 1"/>
        <material name="wheel_collision_mat" rgba="0.8 0.8 0.0 1"/>

        <!-- Ground Materials  -->
        <texture type="2d" name="groundplane" 
            builtin="checker" mark="edge" rgb1="0.2 0.2 0.2" rgb2="0.4 0.4 0.4" 
            markrgb="0.8 0.8 0.8" width="300" height="300" />
        <material name="groundplane" texture="groundplane" texuniform="true" texrepeat="5 5"
            reflectance="0.001"/>
    </asset>


    <worldbody>

        <!-- Ground -->
        <geom name="ground" size="0 0 0.05" pos="0 0 -0.3" type="plane" material="groundplane" contype="1" conaffinity="3" group="0"/>

        <!-- MX340 Vehicle -->
        <body name="mt340_vehicle" pos="0 0 0" quat="1 0 0 0" childclass="autotug">
            <freejoint name="vehicle_freejoint"/>

            <!-- MT340 Body -->
            <body name="mt340_body" pos="0 0 0" quat="1 0 0 0" childclass="autotug">
                <inertial pos="0 0 0" mass="1500" diaginertia="1000 1500 800"/>
                <geom class="body"    type="mesh" mesh="vehicle_mesh" material="vehicle_material"/>
                <!-- <geom class="visual"    type="mesh" mesh="vehicle_mesh" material="vehicle_material"/> -->
                <!-- <geom class="collision" type="mesh" mesh="vehicle_mesh" material="vehicle_material"/> -->
                <site name="rear_tire_center" pos="0 -0.517309 0.5" size="0.02" rgba="1 1 0 1"/>

                <!-- Cart attachment point -->
                <frame name="hitch_frame" pos="0 -0.925 0.0" quat="1 0 0 0">
                    <!-- <joint name="hitch_ball_joint" type="ball"/> -->
                    <site name="hitch_point" pos="0 0 0" size="0.03" rgba="1 1 1 1"/>
                </frame>

                <!-- mt340_front_axle -->
                <body name="mt340_front_axle" pos="0.000198437 0.732631 0.199062" quat="0.7071067 0.0 0.0 0.7071067">
                    <!-- Joint from mt340_body to mt340_front_axle -->
                    <joint axis="0 0 1" name="Revolute-Front-Axle" type="hinge" 
                        ref="0.0"
                        range="-0.6229704491262441 0.5987600272697865"
                        stiffness="1000" damping="100" frictionloss="0.10"
                        armature="1.0"/>
                    <inertial pos="0 0 0" mass="50.0" diaginertia="5 5 5"/>
                    <geom class="shaft"  type="mesh" mesh="front_axle_mesh" material="shaft_material"/>
                    <!-- <geom class="collision" type="mesh" mesh="front_axle_mesh" material="shaft_material"/> -->

                    <!-- Front left wheel -->
                        <!-- Joint from mt340_front_axle to mt340_wheel_front_left -->
                    <body name="mt340_wheel_front_left" pos="0.00  0.186780 -0.261233" quat="0.7071067 -0.7071067 0.0 0.0">
                        <joint axis="0 0 1" name="Revolute-Front-Left" type="hinge" 
                            ref="0.0"
                            damping="100" frictionloss="0.5"/>
                        <inertial pos="0 0 0" mass="10.0" diaginertia="5 5 5"/>
                        <geom class="tires-visual"  type="mesh" mesh="wheel_fl_mesh" material="wheel_mat"/>
                        <geom class="tires-collision" type="cylinder" pos="0 0 -0.083453" size="0.20 0.05" material="wheel_collision_mat" name="wheel_fl_collision"/>

                    </body>

                    <!-- Front right wheel -->
                        <!-- Joint from mt340_front_axle to mt340_wheel_front_right -->
                    <body name="mt340_wheel_front_right" pos="0.00 -0.186780 -0.261233" quat="0.7071067 0.7071067 0.0 0.0">
                        <joint axis="0 0 1" name="Revolute-Front-Right" type="hinge" 
                            damping="0.1" frictionloss="0.01"/>
                        <inertial pos="0 0 0" mass="10.0" diaginertia="5 5 5"/>
                        <geom class="tires-visual"    type="mesh" mesh="wheel_fr_mesh" material="wheel_mat"/>
                        <geom class="tires-collision" type="cylinder" pos="0 0 -0.083453" size="0.20 0.05" material="wheel_collision_mat" name="wheel_fr_collision"/>
                    </body>

                </body>

                <!-- Link mt340_wheel_rear_left -->
                <body name="mt340_wheel_rear_left" pos="-0.409601 -0.517309 -0.0621708" quat="0.0 0.0 0.0 1.0">
                    <!-- Joint from mt340_body to mt340_wheel_rear_left -->
                    <joint axis="1 0 0" name="Revolute-Rear-Left" type="hinge" 
                        damping="0.1" frictionloss="0.01"/>
                    <inertial pos="0 0 0" mass="10.0" diaginertia="5 5 5"/>
                    <geom class="tires-visual"    type="mesh" mesh="wheel_rl_mesh" material="wheel_mat"/>
                    <geom class="tires-collision" type="cylinder" pos="0 0 0" quat="0.7071067 0.0 0.7071067 0.0" size="0.20 0.05" material="wheel_collision_mat" name="wheel_rl_collision"/>
                </body>

                <!-- Link mt340_wheel_rear_right -->
                <body name="mt340_wheel_rear_right" pos="0.423163 -0.517309 -0.0621708" quat="0.0 0.0 0.0 1.0">
                    <!-- Joint from mt340_body to mt340_wheel_rear_right -->
                    <joint axis="1 0 0" name="Revolute-Rear-Right" type="hinge" 
                        damping="0.1" frictionloss="0.01"/>
                    <inertial pos="0 0 0" mass="10.0" diaginertia="5 5 5"/>
                    <geom class="tires-visual"    type="mesh" mesh="wheel_rr_mesh" material="wheel_mat"/>
                    <geom class="tires-collision" type="cylinder" pos="0 0 0" quat="0.7071067 0.0 0.7071067 0.0" size="0.20 0.05" material="wheel_collision_mat" name="wheel_rr_collision"/>
                </body>

            </body>
        </body>

    </worldbody>

    <tendon>
        <!-- Tendon for stable steering control -->
        <fixed name="steering_tendon">
            <joint joint="Revolute-Front-Axle" coef="1"/>
        </fixed>
        
        <!-- Tendon for synchronized rear wheel control -->
        <fixed name="throttle_tendon">
            <joint joint="Revolute-Rear-Left" coef="1"/>
            <joint joint="Revolute-Rear-Right" coef="1"/>
        </fixed>
    </tendon>

    <contact>
        <!-- Wheel-ground contacts with damping -->
        <pair geom1="wheel_fl_collision" geom2="ground" 
            friction="0.8 0.4 0.015"
            solref="0.1 0.5"
            solimp="0.8 0.9 0.01"
            margin="0.001"/>
        <pair geom1="wheel_fr_collision" geom2="ground" 
            friction="0.8 0.4 0.015"
            solref="0.1 0.5"
            solimp="0.8 0.9 0.01"
            margin="0.001"/>
        <pair geom1="wheel_rl_collision" geom2="ground" 
            friction="0.8 0.4 0.015"
            solref="0.1 0.5"
            solimp="0.8 0.9 0.01"
            margin="0.001"/>
        <pair geom1="wheel_rr_collision" geom2="ground" 
            friction="0.8 0.4 0.015"
            solref="0.1 0.5"
            solimp="0.8 0.9 0.01"
            margin="0.001"/>
    </contact>


    <equality>
    </equality>
    
    <actuator>
        <!-- Tendon-based steering (more stable) -->
        <position name="steering_control" 
                  tendon="steering_tendon" 
                  kp="20000" 
                  kv="200" 
                  ctrlrange="-0.6 0.6"
                  forcerange="-1000 1000"/>
        
        <!-- Synchronized throttle via tendon -->
        <motor name="throttle_synchronized" 
               tendon="throttle_tendon" 
               gear="50" 
               ctrlrange="-10 10"/>
        
        <!-- Individual rear wheel control (for differential steering) -->
        <!-- <motor name="throttle_left" 
               joint="Revolute-Rear-Left" 
               gear="25" 
               ctrlrange="-50 50"/>
        
        <motor name="throttle_right" 
               joint="Revolute-Rear-Right" 
               gear="25" 
               ctrlrange="-50 50"/> -->
    </actuator>

</mujoco>
