<?xml version="1.0" ?>

<mujoco model="autoforklift">
    <compiler angle="radian" meshdir="assets" autolimits="true"/>

    <option noslip_iterations="10" noslip_tolerance="1e-6"/>

    <option>
        <flag gravity="enable"/>
    </option>

    <!-- Enhanced no-slip solver -->
    <option timestep="0.005"
            iterations="20"
            tolerance="1e-12"
            solver="Newton"
            jacobian="dense"
            noslip_iterations="10"
            noslip_tolerance="1e-6"/>

    <default>
        <default class="autoforklift">
            <joint frictionloss="0.1" armature="0.005"/>
            <position kp="50" dampratio="1"/>

            <default class="body">
                <geom type="mesh" contype="1" conaffinity="0" group="1"/>
            </default>

            <default class="hits-ground-not-body">
                <geom type="mesh" contype="1" conaffinity="0" group="1"/>
            </default>

            <default class="shaft">
                <geom type="mesh" contype="0" conaffinity="0" group="2"/>
            </default>

            <!-- Visual geom only -->
            <default class="visual-only">
                <geom type="mesh" contype="0" conaffinity="0" group="2"/>
            </default>

            <default class="tires-visual">
                <geom type="mesh" contype="0" conaffinity="0" group="2"/>
            </default>
            <default class="tires-collision">
                <geom type="mesh" contype="2" conaffinity="2" group="2"/>
            </default>

        </default>
    </default>


    <asset>
        <!-- Vehicle Materials  -->
        <mesh name="body_mesh" file="BOA3000-BODY.stl"/>
        <mesh name="roller_mesh" file="BOA3000-ROLLER.stl"/>
        <mesh name="shaft_mesh" file="BOA3000-STEERING-SHAFT.stl"/>
        <mesh name="wheel_mesh" file="BOA3000-TRACTION-WHEEL.stl"/>
        <mesh name="tiller_base_mesh" file="BOA3000-TILLER-BASE.stl"/>
        <mesh name="tiller_handle_mesh" file="BOA3000-TILLER-HANDLE.stl"/>
        <mesh name="mast_mesh" file="BOA3000-MAST.stl"/>
        <mesh name="lift_mesh" file="BOA3000-LIFT.stl"/>
        <mesh name="fork_lift_mesh" file="BOA3000-FORK-LIFT.stl"/>
        <mesh name="forks_tilter_mesh" file="BOA3000-FORKS-TILTER.stl"/>
        <mesh name="left_fork_tine_mesh" file="BOA3000-LEFT-FORK-TINE.stl"/>
        <mesh name="right_fork_tine_mesh" file="BOA3000-RIGHT-FORK-TINE.stl"/>

        <material name="vehicle_material" rgba="0.4 0.3 0.0 1"/>
        <material name="mast_material" rgba="0.1 0.1 0.1 1"/>
        <material name="lift_material" rgba="0.15 0.15 0.15 1"/>
        <material name="fork_lift_material" rgba="0.2 0.2 0.2 1"/>
        <material name="forks_tilter_material" rgba="0.3 0.3 0.3 1"/>
        <material name="fork_tines_material" rgba="0.1 0.1 0.1 1"/>
        <material name="tiller_material" rgba="0.1 0.1 0.1 1"/>
        <material name="roller_material" rgba="0.6 0.6 0.4 1"/>
        <material name="shaft_material" rgba="0.2 0.2 0.2 1"/>
        <material name="wheel_material" rgba="0.2 0.2 0.2 1"/>
        <material name="wheel_collision_material" rgba="0.8 0.0 0.0 1"/>

        <!-- Ground Materials  -->
        <texture type="2d" name="groundplane" 
            builtin="checker" mark="edge" rgb1="0.2 0.2 0.2" rgb2="0.4 0.4 0.4" 
            markrgb="0.8 0.8 0.8" width="300" height="300" />
        <material name="groundplane" texture="groundplane" texuniform="true" texrepeat="5 5"
            reflectance="0.001"/>
    </asset>

    <worldbody>

        <!-- Ground -->
        <geom name="ground" size="0 0 0.1" pos="0 0 0" type="plane" material="groundplane" contype="1" conaffinity="3" group="0"/>

        <!-- BOA3000 Vehicle -->
        <body name="boa3000_vehicle" pos="0 0 0.10" quat="1 0 0 0">
            <freejoint name="vehicle_freejoint"/>

            <!-- BOA3000 Body -->
            <body name="boa3000_body" pos="0 0 0" quat="1 0 0 0" childclass="autoforklift">
                <inertial pos="-0.65 0 0.5" mass="2000" diaginertia="400 500 500"/>
                <geom class="body" type="mesh" mesh="body_mesh" pos="-1.009471 0 -0.077436" quat="0.5 0.5 -0.5 -0.5" material="vehicle_material"/>

                <site name="rear_tire_center" pos="0 0 0" size="0.02" rgba="1 1 0 1"/>

                <!-- BOA3000 LEFT ROLLER -->
                <body name="boa3000_left_roller" pos="0 -0.439000 0" quat="0.7071067 0.7071067 0 0">
                    <joint axis="0 0 1" name="Revolute-Left-Roller" type="hinge" 
                        ref="0.0"
                        damping="100" frictionloss="0.5"/>
                    <inertial pos="0 0 0" mass="5.0" diaginertia="0.5 0.5 1"/>
                    <geom class="tires-visual" type="mesh" mesh="roller_mesh" material="roller_material"/>
                    <geom class="tires-collision" type="cylinder" pos="0 0 0" size="0.0749 0.03" material="wheel_collision_material" name="wheel_left_collision"/>
                </body>

                <!-- BOA3000 RIGHT ROLLER -->
                <body name="boa3000_right_roller" pos="0  0.439000 0" quat="0.7071067 0.7071067 0 0">
                    <joint axis="0 0 1" name="Revolute-Right-Roller" type="hinge" 
                        ref="0.0"
                        damping="100" frictionloss="0.5"/>
                    <inertial pos="0 0 0" mass="5.0" diaginertia="0.5 0.5 1"/>
                    <geom class="tires-visual" type="mesh" mesh="roller_mesh" material="roller_material"/>
                    <geom class="tires-collision" type="cylinder" pos="0 0 0" size="0.0749 0.03" material="wheel_collision_material" name="wheel_right_collision"/>
                </body>


                <!-- BOA3000 Steering shaft -->
                <body name="boa3000_steering_shaft" pos="-1.009472 0.005091 0.044064" quat="0.5 0.5 -0.5 -0.5">
                    <joint pos="0 0 0.170000" axis="0 1 0" name="Revolute-Front-Axle" type="hinge" 
                        ref="0.0"
                        range="-0.6 0.6"
                        stiffness="1000" damping="100" frictionloss="0.10"
                        armature="1.0"/>
                    <inertial pos="0 0 0" mass="50.0" diaginertia="5 5 5"/>
                    <geom class="shaft"  type="mesh" mesh="shaft_mesh" material="shaft_material"/>

                    <!-- BOA3000 TRACTION WHEEL -->
                    <body name="boa3000_traction_wheel" pos="0 0 0" quat="1 0 0 0">
                        <joint pos="-0.022367 0.002500 0.169965" axis="-1 0 0" name="Revolute-Traction-Wheel" type="hinge" 
                            ref="0.0"
                            damping="100" frictionloss="0.5"/>
                        <geom class="tires-visual" type="mesh" mesh="wheel_mesh" material="roller_material"/>
                        <geom class="tires-collision" type="cylinder" pos="0.011528 0.002500 0.170018" quat="0.7071067 0 0.7071067 0" size="0.123 0.03" material="wheel_collision_material" name="wheel_traction_collision"/>
                        <inertial pos="0.011528 0.002500 0.170018" mass="50.0" diaginertia="5 5 5"/>
                    </body>

                    <!-- BOA3000 TILLER BASE -->
                    <body name="boa3000_tiller_base" pos="0 0 0" quat="1 0 0 0">
                        <inertial pos="0 0 0" mass="10.0" diaginertia="1 1 1"/>
                        <geom class="shaft" type="mesh" mesh="tiller_base_mesh" material="tiller_material"/>
                    </body>

                    <!-- BOA3000 TILLER HANDLE -->
                    <body name="boa3000_tiller_handle" pos="0 0 0" quat="1 0 0 0">
                        <inertial pos="0 0 0" mass="10.0" diaginertia="1 1 1"/>
                        <geom class="shaft" type="mesh" mesh="tiller_handle_mesh" material="tiller_material"/>
                    </body>

                </body>

                <!-- BOA3000 MAST -->
                <body name="boa3000_mast" pos="-1.009471 0 -0.077436" quat="0.5 0.5 -0.5 -0.5">
                    <inertial pos="0 0 0" mass="50.0" diaginertia="5 5 5"/>
                    <geom class="shaft" type="mesh" mesh="mast_mesh" material="mast_material"/>
                    <site name="lift_start_site" pos="0.007000 0.136659 -0.829827" size="0.01" rgba="1 0 0 1"/>

                    <!-- BOA3000 MAST LIFT -->
                    <body name="boa3000_lift" pos="0.007000 0.136659 -0.829827" quat="0.5 0.5 0.5 -0.5">
                        <joint pos="0 0 0" axis="0 0 -1" name="Prismatic-Mast-Lift-Joint" type="slide" 
                            ref="0.0"
                            range="-0.0 1.65"
                            damping="100" frictionloss="0.5"/>
                        <inertial pos="0 0 0" mass="10.0" diaginertia="1 1 1"/>
                        <geom class="visual-only" type="mesh" mesh="lift_mesh" material="lift_material"/>

                        <!-- BOA3000 FORK LIFT -->
                        <body name="boa3000_fork_lift" pos="0 0 0" quat="1 0 0 0">
                            <joint pos="0 0 0" axis="0 0 -1" name="Prismatic-Fork-Lift-Joint" type="slide" 
                                ref="0.0"
                                range="-0.0 1.65"
                                damping="100" frictionloss="0.5"/>
                            <inertial pos="0 0 0" mass="10.0" diaginertia="1 1 1"/>
                            <geom class="visual-only" type="mesh" mesh="fork_lift_mesh" material="fork_lift_material"/>
                            <site name="lift_end_site" pos="0 0 0" size="0.01" rgba="0 1 0 1"/>

                            <!-- BOA3000 FORKS TILTER -->
                            <body name="boa3000_forks_tilter" pos="0 0 0" quat="1 0 0 0">
                                <joint pos="0.162947 0.0 -0.385079" axis="0 1 0" name="Revolute-Fork-Tilter-Joint" type="hinge" 
                                    ref="0.0"
                                    range="-0.05 0.05"
                                    damping="100" frictionloss="0.5"/>
                                <inertial pos="0 0 0" mass="10.0" diaginertia="1 1 1"/>
                                <geom class="hits-ground-not-body" type="mesh" mesh="forks_tilter_mesh" pos="1.233025 -0.002500 -0.381436" quat="0 0 0 1" material="forks_tilter_material"/>

                                <!-- BOA3000 IMPLEMENT FRAME - to be used for attaching other implements -->
                                <frame name="implement_frame" pos="0 0 0" quat="1 0 0 0">
                                    <!-- BOA3000 LEFT TINE -->
                                    <body name="boa3000_left_fork_tine" pos="0 0 0" quat="1 0 0 0">
                                        <inertial pos="0 0 0" mass="10.0" diaginertia="1 1 1"/>
                                        <geom class="hits-ground-not-body" type="mesh" mesh="left_fork_tine_mesh" pos="0.177 0.002500 0.041" quat="0 -0.7071067 0 0.7071067" material="fork_tines_material"/>
                                    </body>

                                    <!-- BOA3000 RIGHT TINE -->
                                    <body name="boa3000_right_fork_tine" pos="0 0 0" quat="1 0 0 0">
                                        <inertial pos="0 0 0" mass="10.0" diaginertia="1 1 1"/>
                                        <geom class="hits-ground-not-body" type="mesh" mesh="right_fork_tine_mesh" pos="0.177 0.002500 0.041" quat="0 -0.7071067 0 0.7071067" material="fork_tines_material"/>
                                    </body>

                                    <frame name="longbow_frame" pos="0.237251 -0.005 -0.91414" quat="0 0.7071067 -0.7071067 0">
                                        <geom class="body" type="sphere" size="0.01" rgba="0 1 0 1"/>                        
                                    </frame>

                                </frame>

                            </body>

                        </body>

                    </body>

                </body>

            </body>

        </body>

    </worldbody>

    <contact>
        <!-- Wheel-ground contacts with damping -->
        <pair geom1="wheel_left_collision" geom2="ground" 
            friction="0.99 0.99 0.99"
            solref="0.1 0.5"
            solimp="0.8 0.9 0.01"
            margin="0.010"/>
        <pair geom1="wheel_right_collision" geom2="ground" 
            friction="0.99 0.99 0.99"
            solref="0.1 0.5"
            solimp="0.8 0.9 0.01"
            margin="0.010"/>
        <pair geom1="wheel_traction_collision" geom2="ground" 
            friction="0.99 0.99 0.99"
            solref="0.1 0.5"
            solimp="0.8 0.9 0.01"
            margin="0.010"/>
    </contact>


    <equality>
        <joint joint1="Prismatic-Mast-Lift-Joint" joint2="Prismatic-Fork-Lift-Joint" polycoef="0 1 0 0 0"/>
    </equality>
    
    <tendon>
        <!-- Tendon for steering control -->
        <fixed name="steering_tendon">
            <joint joint="Revolute-Front-Axle" coef="1"/>
        </fixed>
        
        <!-- Tendon for front wheel control -->
        <fixed name="throttle_tendon">
            <joint joint="Revolute-Traction-Wheel" coef="1"/>
        </fixed>

        <!-- Tendon for lift control -->
        <fixed name="lift_tendon">
            <joint joint="Prismatic-Mast-Lift-Joint" coef="1"/>
        </fixed>

        <!-- Tendon for tilt control -->
        <fixed name="tilt_tendon">
            <joint joint="Revolute-Fork-Tilter-Joint" coef="1"/>
        </fixed>

    </tendon>

    <actuator>
        <!-- Tendon-based steering -->
        <position name="STEER" 
                  tendon="steering_tendon" 
                  kp="20000" 
                  kv="200" 
                  ctrlrange="-0.6 0.6"
                  forcerange="-1000 1000"/>

        <!-- Tendon-based throttle -->
        <motor name="THROTTLE" 
               tendon="throttle_tendon" 
               gear="100" 
               ctrlrange="-10 10"/>

        <!-- Tendon-based lift -->
        <position name="LIFT" 
                  tendon="lift_tendon" 
                  kp="20000" 
                  kv="5000"
                  ctrlrange="0 1.70"
                  forcerange="-100000 100000"/>

        <!-- Tendon-based tilt -->
        <position name="TILT" 
                  tendon="tilt_tendon" 
                  kp="50000" 
                  kv="1000"
                  ctrlrange="-0.1 0.1"
                  forcerange="-100000 100000"/>

    </actuator>

</mujoco>
